Workbook

Sheet Corpus
A1: ID | B1: Title | C1: Authors | D1: Year | E1: Venue | F1: Type | G1: Publisher / Index | H1: Found via | I1: Relevance | J1: Technique / role | K1: Link | L1: Notes
A2: 1 | B2: CertiQ: contract-based verification of a realistic quantum compiler | C2: Shi, Li, Tao, Javadi-Abhari, Cross, Chong, Gu | D2: 2019 | E2: arXiv (cs.PL/quant-ph) | F2: Preprint | G2: arXiv | H2: GS p1/p3 | I2: Yes | J2: Compiler verification (C7) | K2: arxiv.org/abs/1908.08963 | L2: Verifies Qiskit passes; finds 3 bugs
A3: 2 | B3: QDiff: Differential testing of quantum software stacks | C3: Wang, Zhang, Xu, Kim | D3: 2021 | E3: ASE | F3: Conference | G3: IEEE Xplore | H3: GS p1 | I3: Yes | J3: Differential testing (C2) | K3: ieeexplore.ieee.org | L3: Cross-stack differential oracle
A4: 3 | B4: Giallar: Push-button verification for the Qiskit quantum compiler | C4: Tao, Shi, Yao, Li, Javadi-Abhari, Cross, Chong, Gu | D4: 2022 | E4: PLDI | F4: Conference | G4: ACM DL | H4: GS p1 | I4: Yes | J4: Compiler verification (C7) | K4: dl.acm.org | L4: Verified 44/56 passes
A5: 4 | B5: MorphQ: Metamorphic testing of the Qiskit quantum computing platform | C5: Paltenghi, Pradel | D5: 2023 | E5: ICSE | F5: Conference | G5: IEEE Xplore | H5: Verified (refs) | I5: Yes | J5: Metamorphic (C3) | K5: arxiv.org/abs/2206.01111 | L5: 13 bugs; ICSE co-listed ACM DL
A6: 5 | B6: MorphQ++: A reproducibility study of metamorphic testing on quantum compilers | C6: Kitt et al. | D6: 2024 | E6: ASE Workshops | F6: Workshop | G6: IEEE Xplore | H6: Verified (refs) | I6: Yes | J6: Metamorphic (C3) | L6: Co-listed ACM DL
A7: 6 | B7: QEMI: A quantum software stacks testing framework via equivalence modulo inputs | C7: Luo, Xia, Zhang, Zhao | D7: 2026 | E7: FASE | F7: Conference | G7: SpringerLink | H7: Verified (refs) | I7: Yes | J7: Equivalence modulo inputs (C4) | K7: arxiv.org/abs/2602.09942 | L7: EMI adapted to quantum
A8: 7 | B8: QuCheck: A property-based testing framework for quantum programs in Qiskit | C8: Pontolillo et al. | D8: 2025 | E8: arXiv | F8: Preprint | G8: arXiv | H8: Verified (refs) | I8: Yes | J8: Property-based (C5) | K8: arxiv.org/abs/2503.22641
A9: 8 | B9: QuteFuzz: Fuzzing quantum compilers using randomly generated circuits | C9: Iwumbwe, Liu, Wickerson | D9: 2025 | E9: PLanQC (POPL workshop) | F9: Workshop | G9: ACM DL | H9: Verified (refs) | I9: Yes | J9: Random generation / fuzzing (C1) | L9: 17 bugs across Qiskit/Cirq/Pytket
A10: 9 | B10: QSPE: Enumerating skeletal quantum programs for quantum library testing | C10: Ye et al. | D10: 2026 | E10: arXiv | F10: Preprint | G10: arXiv | H10: Verified (refs) | I10: Yes | J10: Differential testing (C2) | K10: arxiv.org/abs/2602.00024
A11: 10 | B11: Benchmarking the performance of quantum computing software (Benchpress) | C11: Nation, Saki, Brandhofer et al. | D11: 2025 | E11: Nature Computational Science | F11: Journal | G11: Springer Nature (Nature) | H11: Verified (refs) | I11: Yes | J11: Benchmark (RQ4) | L11: Performance benchmarking suite
A12: 11 | B12: Bugs4Q: A benchmark of existing bugs for controlled testing of quantum programs | C12: Zhao, Zhao, Miao, Lan | D12: 2023 | E12: Journal of Systems and Software | F12: Journal | G12: ScienceDirect (Elsevier) | H12: Verified (refs) | I12: Yes | J12: Bug benchmark (RQ4) | L12: Also ASE 2021 short version
A13: 12 | B13: Advanced equivalence checking for quantum circuits | C13: Burgholzer, Wille | D13: 2021 | E13: IEEE TCAD | F13: Journal | G13: IEEE Xplore | H13: Verified (refs) | I13: Yes | J13: Equivalence checking (C6) | L13: Translation-validation lineage
A14: 13 | B14: Verifying results of the IBM Qiskit quantum circuit compilation flow | C14: Burgholzer, Raymond, Wille | D14: 2020 | E14: IEEE QCE | F14: Conference | G14: IEEE Xplore | H14: Verified (refs) | I14: Yes | J14: Equivalence checking (C6)
A15: 14 | B15: Equivalence checking of quantum circuits via path-sum and weighted model counting | C15: Mei et al. | D15: 2026 | E15: TACAS | F15: Conference | G15: SpringerLink | H15: Verified (refs) | I15: Yes | J15: Equivalence checking (C6)
A16: 15 | B16: Concolic testing for quantum compilers | C16: Choudhury, Bhave, Basu | D16: 2025 | E16: IEEE ICCD | F16: Conference | G16: IEEE Xplore | H16: GS p1 | I16: Yes | J16: Concolic / symbolic (C1) | K16: ieeexplore.ieee.org | L16: Finds missed optimisations
A17: 16 | B17: Statistical testing of quantum programs via fixed-point amplitude amplification | C17: Kang, Lee, Oh | D17: 2024 | E17: OOPSLA | F17: Conference | G17: ACM DL | H17: Verified (refs) | I17: Yes | J17: Statistical oracle (RQ2) | L17: Repeated-measurement oracle
A18: 17 | B18: Exact inference for quantum circuits: a testing oracle for quantum software stacks | C18: Lee, Hong, Ryu | D18: 2025 | E18: ASE | F18: Conference | G18: IEEE Xplore | H18: Verified (refs) | I18: Yes | J18: Testing oracle (RQ2) | L18: Co-listed ACM DL
A19: 18 | B19: Bugs in quantum computing platforms: an empirical study | C19: Paltenghi, Pradel | D19: 2022 | E19: OOPSLA | F19: Conference | G19: ACM DL | H19: GS p1 | I19: Yes | J19: Empirical bug study (RQ1) | K19: dl.acm.org | L19: 39.9% quantum-specific bugs
A20: 19 | B20: A survey on testing and analysis of quantum software | C20: Paltenghi, Pradel | D20: 2024 | E20: arXiv | F20: Preprint (survey) | G20: arXiv | H20: GS p1 | I20: Yes (secondary) | J20: Survey | K20: arxiv.org/abs/2410.00650 | L20: Broad QS testing survey
A21: 20 | B21: A survey on fuzz testing for quantum computing | C21: Betanzo | D21: 2025 | E21: IEEE CHILECON | F21: Conference | G21: IEEE Xplore | H21: GS p2 | I21: Yes (secondary) | J21: Survey / fuzzing | K21: ieeexplore.ieee.org
A22: 21 | B22: An experience-based classification of quantum bugs in quantum software | C22: Quetschlich, Di Matteo | D22: 2025 | E22: Computing (Springer) | F22: Journal | G22: SpringerLink | H22: GS p2 | I22: Maybe | J22: Bug taxonomy | L22: Quantum bugs, not compiler-specific
A23: 22 | B23: IterTestQ: Assembly-level, cross-platform testing of quantum computing platforms | C23: Paltenghi, Pradel | D23: 2026 | E23: Preprint (venue TBD) | F23: Preprint | G23: arXiv | H23: GS p3 | I23: Yes | J23: Differential testing (C2) | K23: software-lab.org | L23: Newer than survey
A24: 23 | B24: Muskit: A mutation analysis tool for quantum software testing | C24: Mendiluze, Ali, Yue, Arcaini | D24: 2021 | E24: ASE | F24: Conference | G24: IEEE Xplore | H24: Verified (refs) | I24: Yes | J24: Mutation testing | L24: Co-listed ACM DL
A25: 24 | B25: QMutPy / Mutation testing of quantum programs: a case study with Qiskit | C25: Fortunato, Campos, Abreu | D25: 2022 | E25: IEEE TQE | F25: Journal | G25: IEEE Xplore | H25: Verified (refs) | I25: Yes | J25: Mutation testing
A26: 25 | B26: A verified optimizer for quantum circuits (VOQC) | C26: Hietala, Rand, Hung, Wu, Hicks | D26: 2021 | E26: POPL | F26: Conference | G26: ACM DL | H26: Verified (refs) | I26: Yes | J26: Compiler verification (C7) | L26: Coq-verified optimiser
A27: 26 | B27: Verified compilation of quantum oracles | C27: Li, Voichick, Hietala, Peng, Wu et al. | D27: 2022 | E27: OOPSLA | F27: Conference | G27: ACM DL | H27: GS p1 | I27: Maybe | J27: Compiler verification (C7) | K27: dl.acm.org | L27: 'oracle' = algorithmic, borderline
A28: 27 | B28: Automating the comparison of quantum compilers for quantum circuits | C28: Salm, Barzen, Leymann, Weder | D28: 2021 | E28: Springer symposium | F28: Conference | G28: SpringerLink | H28: GS p3 | I28: Maybe | J28: Compiler evaluation | L28: Evaluation infrastructure
A29: 28 | B29: Quamap: A multi-backend benchmark dataset for quantum circuit mapping | C29: Zhao, Li, Yin | D29: 2026 | E29: ACM SIGKDD | F29: Conference | G29: ACM DL | H29: GS p1 | I29: Maybe | J29: Benchmark / mapping (RQ4) | K29: dl.acm.org
A30: 29 | B30: Projection-based runtime assertions for testing and debugging quantum programs | C30: Li, Zhou, Yu, Ding, Ying, Xie | D30: 2020 | E30: OOPSLA (PACMPL) | F30: Conference | G30: ACM DL | H30: GS p4 | I30: Yes (secondary) | J30: Runtime assertion oracle (RQ2) | K30: dl.acm.org | L30: 175 citations; assertion-based oracle for QP testing
A31: 30 | B31: Shaking up quantum simulators with fuzzing and rigour | C31: Klimis, Bensoussan, Chachkarova et al. | D31: 2025 | E31: ACM (proceedings; exact venue truncated in listing) | F31: Conference | G31: ACM DL | H31: GS p4 | I31: Yes (secondary) | J31: Fuzzing + differential testing | K31: dl.acm.org | L31: Targets simulators, not compiler; confirm venue on full text
A32: 31 | B32: QuraTest: Integrating quantum specific features in quantum program testing | C32: Ye, Xia, Zhang, Arcaini, Ma et al. | D32: 2023 | E32: ASE | F32: Conference | G32: IEEE Xplore | H32: GS p4 | I32: Yes | J32: Quantum program testing framework (RQ1) | K32: ieeexplore.ieee.org | L32: Co-listed ACM DL
A33: 32 | B33: Arline benchmarks: Automated benchmarking platform for quantum compilers | C33: Kharkov, Ivanova, Mikhantiev et al. | D33: 2022 | E33: arXiv | F33: Preprint | G33: arXiv | H33: GS p5 | I33: Yes (secondary) | J33: Benchmark (RQ4) | K33: arxiv.org | L33: Compares compiler-framework performance
A34: 33 | B34: A Mutation-Based Framework for Efficiency Evaluation of Quantum Compilers | C34: Jiang, Yang, Liu, Deng, Huang | D34: 2025 | E34: SSRN working paper | F34: Preprint | G34: SSRN | H34: GS p5 | I34: Yes | J34: Mutation testing / compiler evaluation | K34: papers.ssrn.com | L34: Year approximate (SSRN id 6997092); tests SABRE/QMAP/FiDLS
A35: 34 | B35: Quantum software engineering: Landscapes and horizons | C35: Zhao | D35: 2020 | E35: arXiv | F35: Preprint (survey) | G35: arXiv | H35: GS p7 | I35: Maybe | J35: Survey / landscape (background) | K35: arxiv.org | L35: 314 citations; broad QSE survey incl. bug patterns
A36: 35 | B36: Quantum Mutant Equivalence via Transpilation | C36: Campos, Miranskyy | D36: 2026 | E36: arXiv | F36: Preprint | G36: arXiv | H36: GS eq-check | I36: Yes | J36: Mutation + equivalence via transpilation (C2/C4) | K36: arxiv.org | L36: Uses transpilation itself as an equivalence oracle
A37: 36 | B37: QuaSi: A scalable and reliable quantum simulation-based equivalence checking framework | C37: Lu, Choudhury, Basu | D37: 2024 | E37: IEEE Conf. on Quantum Computing & Engineering (venue truncated) | F37: Conference | G37: IEEE Xplore | H37: GS eq-check | I37: Yes | J37: Equivalence checking (C6) | K37: ieeexplore.ieee.org | L37: Verifies transpilation correctness
A38: 37 | B38: Practical verification of quantum circuit transformations | C38: Ricciardi | D38: 2026 | E38: PhD thesis, HAL | F38: Thesis | G38: Other | H38: GS eq-check | I38: Yes | J38: Compiler-transformation verification (C6/C7) | K38: theses.hal.science
A39: 38 | B39: Scalable Compilation and Equivalence Checking of Quantum Circuits | C39: Moflic | D39: 2024 | E39: MSc/PhD thesis, Aalto University | F39: Thesis | G39: Other | H39: GS eq-check | I39: Maybe | J39: Compilation + equivalence checking (C6) | K39: aaltodoc.aalto.fi | L39: QEC-focused; compilation is secondary theme
A40: 39 | B40: Automated equivalence checking of concurrent quantum systems | C40: Ardeshir-Larijani, Gay, Nagarajan | D40: 2018 | E40: ACM Transactions on Computational Logic | F40: Journal | G40: ACM DL | H40: GS eq-check | I40: Yes | J40: Equivalence checking (C6), foundational | K40: dl.acm.org
...

Sheet Summary
A1: Scoping corpus — where the papers are published
A2: Counts computed live from the Corpus tab (COUNTIF). Edit Corpus and re-open to refresh.
A4: Publisher / Index | B4: Papers | D4: Type | E4: Papers | G4: Relevance | H4: Papers
A5: IEEE Xplore | B5: =COUNTIF(Corpus!$G$2:$G$301,A5) -> 78 | D5: Journal | E5: =COUNTIF(Corpus!$F$2:$F$301,D5) -> 65 | G5: Yes | H5: =COUNTIF(Corpus!$I$2:$I$301,G5) -> 237
A6: ACM DL | B6: =COUNTIF(Corpus!$G$2:$G$301,A6) -> 72 | D6: Conference | E6: =COUNTIF(Corpus!$F$2:$F$301,D6) -> 112 | G6: Yes (secondary) | H6: =COUNTIF(Corpus!$I$2:$I$301,G6) -> 16
A7: SpringerLink | B7: =COUNTIF(Corpus!$G$2:$G$301,A7) -> 35 | D7: Workshop | E7: =COUNTIF(Corpus!$F$2:$F$301,D7) -> 28 | G7: Maybe | H7: =COUNTIF(Corpus!$I$2:$I$301,G7) -> 47
A8: Springer Nature (Nature) | B8: =COUNTIF(Corpus!$G$2:$G$301,A8) -> 1 | D8: Preprint | E8: =COUNTIF(Corpus!$F$2:$F$301,D8) -> 75 | G8: Total | H8: =SUM(H5:H7) -> 300
A9: ScienceDirect (Elsevier) | B9: =COUNTIF(Corpus!$G$2:$G$301,A9) -> 1 | D9: Preprint (survey) | E9: =COUNTIF(Corpus!$F$2:$F$301,D9) -> 2
A10: arXiv | B10: =COUNTIF(Corpus!$G$2:$G$301,A10) -> 68 | D10: Thesis | E10: =COUNTIF(Corpus!$F$2:$F$301,D10) -> 12
A11: SSRN | B11: =COUNTIF(Corpus!$G$2:$G$301,A11) -> 2 | D11: Book chapter | E11: =COUNTIF(Corpus!$F$2:$F$301,D11) -> 6
A12: Wiley | B12: =COUNTIF(Corpus!$G$2:$G$301,A12) -> 1 | D12: Total | E12: =SUM(E5:E11) -> 300
A13: Other | B13: =COUNTIF(Corpus!$G$2:$G$301,A13) -> 42
A14: Total | B14: =SUM(B5:B13) -> 300
A17: By year
A18: Year | B18: Papers
A19: 2015 | B19: =COUNTIF(Corpus!$D$2:$D$301,A19) -> 0
A20: 2016 | B20: =COUNTIF(Corpus!$D$2:$D$301,A20) -> 0
A21: 2017 | B21: =COUNTIF(Corpus!$D$2:$D$301,A21) -> 0
A22: 2018 | B22: =COUNTIF(Corpus!$D$2:$D$301,A22) -> 3
A23: 2019 | B23: =COUNTIF(Corpus!$D$2:$D$301,A23) -> 8
A24: 2020 | B24: =COUNTIF(Corpus!$D$2:$D$301,A24) -> 10
A25: 2021 | B25: =COUNTIF(Corpus!$D$2:$D$301,A25) -> 20
A26: 2022 | B26: =COUNTIF(Corpus!$D$2:$D$301,A26) -> 26
A27: 2023 | B27: =COUNTIF(Corpus!$D$2:$D$301,A27) -> 30
A28: 2024 | B28: =COUNTIF(Corpus!$D$2:$D$301,A28) -> 52
A29: 2025 | B29: =COUNTIF(Corpus!$D$2:$D$301,A29) -> 70
A30: 2026 | B30: =COUNTIF(Corpus!$D$2:$D$301,A30) -> 81
A31: Total | B31: =SUM(B19:B30) -> 300
A32: Screened but excluded (off-topic / not related to SLR)
A33: Round | B33: Excluded (irrelevant) | D33: Notes
A34: 1-6 | B34: (not logged) | D34: Exclusions were not separately logged during rounds 1-6 — only included/screened-in papers were recorded at the time. Running total starts from Round 7.
A35: 7 | B35: 8 | D35: Off-topic/too-broad hits from the 5 new queries this round: 4 quantum-SE/QC surveys too broad to be testing-specific (Gill et al. taxonomy, Salam & Ilyas MLR, Dwivedi et al. lifecycle survey, Mandal et al. SE review), 1 tangential ML-platform paper (QuantuMoonLight), 1 non-research editorial (Eldh), 1 hardware performance-benchmark paper (Lubinski et al.), 1 compiler-architecture paper without a testing focus (Scheller et al.). Duplicates of papers already in the corpus are not counted here (tracked separately as screening dedupe, not exclusion).
A36: 8 | B36: 14 | D36: Off-topic hits from the 5 new round-8 queries: 6 QML-training/hardware-physics papers with no software-testing focus (Dalyac et al., Khanal, Ayral et al., QuantumNAT, RobustState, RoQNN), 2 symbolic-execution/formalism papers too theoretical or too broad to be testing-specific (Ying 2025 symbolic specification, Miszczak symbolic programming), 1 broad quantum-systems review (Yin et al.), 2 broad/low-tier framework overview articles (Rusum & Anasuri, Nalwade & Upoma), and 3 classical (non-quantum) compiler-fuzzing papers returned by the PennyLane/Braket query (Cummins et al., Ye et al., Palka et al.) that are out of scope by design. Duplicates of papers already in the corpus are not counted here.
A37: 9 | B37: 5 | D37: Off-topic hits from the 5 new round-9 queries: 1 tangential LLM circuit-generation paper (Macarone-Palmieri & Franco, not a testing study), 1 design-patterns case study with no testing focus (Fernandez-Osuna et al.), 1 quantum-annealing-for-classical-test-suite-optimization paper excluded per the protocol's Table 6 confound rule (Trovato et al. — quantum optimisation applied to classical testing, not testing of quantum software), 1 broad open-source-ecosystem landscape paper (Fingerhuth et al., testing is a minor aspect among many), and 1 broad PhD dissertation on heterogeneous-computing testing/debugging that overlaps material already captured via its constituent QDiff and equivalence-rules papers already in the corpus (Wang J. dissertation). Duplicates of papers already in the corpus (including same-author thesis/technical-report/artifact companions) are not counted here.
A38: 10 | B38: 49 | D38: Round 10 ran 10 queries (two batches of 5) targeting: metamorphic relations for Shor/Grover, VQE/QAOA testing/validation, test-case prioritisation/selection, error-mitigation (ZNE) testing, runtime verification, test-oracle generation, search-based/genetic test generation, unit-testing frameworks, CI adoption empirical studies, and design-by-contract. Two query angles turned out to probe adjacent-but-out-of-scope literatures almost entirely: (a) VQE/QAOA 'testing/validation' and error-mitigation (ZNE) 'testing' mostly return physics/algorithm-performance benchmarking papers, not software-testing-of-compilers papers (13 excluded across these two queries); (b) test-case prioritisation/selection returns almost exclusively the quantum-annealing-for-classical-test-suite-optimization confound already flagged by the protocol's Table 6 exclusion rule, plus two classical quantum-behaved-PSO papers that are not quantum computing at all (9 excluded). Also excluded: 3 post-quantum-cryptography hits misidentified by keyword overlap ('quantum' meaning quantum-resistant classical crypto, not quantum computing: Pugh et al., Abela et al., Sun et al.), 1 false-positive keyword match unrelated to quantum computing (Platzer — 'Quantum' is a variable name in a cyber-physical-systems example), several QNN/architecture-search papers using genetic algorithms for circuit optimisation rather than testing, 8 classical (non-quantum) CI-adoption empirical studies returned by the CI query, and a handful of broad roadmap/ecosystem/toolchain/pattern-catalog papers with no testing focus. Duplicates of papers already in the corpus (including same-author thesis/preprint/poster companions) are not counted here.
A39: 11 | B39: 16 | D39: Off-topic hits from the 5 new round-11 queries: 1 pure-theory ZX-calculus completeness proof with no testing/verification-tool angle (Wang 2022), 5 classical (non-quantum-specific) LLM-code-generation/testing surveys and tools returned by the Copilot query (Fan et al., Wang et al., Agarwal et al., Menet et al., Mathews), and 10 quantum-compiler qubit-allocation/mapping algorithm-design papers returned by the qubit-placement query that address compiler heuristics and their empirical performance rather than a testing methodology (Murali et al., LeCompte et al., Chipmunq, QuantEM, 2qan, Siraichi et al., Zhu et al. survey, Wille et al., FQAS, Promponas et al.) — this negative finding narrows the qubit-mapping literature to a compiler-design topic distinct from our testing/verification scope. The GitHub-issue/transpiler-bug empirical-mining query returned zero new papers, all 10 hits already captured in the corpus from earlier rounds — a useful signal that this vein is now saturated. Duplicates of papers already in the corpus (including same-author thesis/book-chapter companions) are not counted here.
A40: 12 | B40: 12 | D40: Round 12 was a short targeted round (3 queries) run to close the gap to the user's requested 200-row target: Clifford/stabilizer circuit verification, compiler rewrite-rule correctness (peephole optimization), and a second page of the round-9 circuit-synthesis query. Excluded: 6 physics/complexity-theory papers using 'verification'/'testing' in the quantum-information-theory sense (property testing of Clifford-ness, QMA complexity, fault-tolerance benchmarking) rather than the software-testing sense (Xiao et al., Brown et al., Yan, Sun et al., Arunachalam et al., Kuehnke et al.), 1 classical (non-quantum) SSA-compiler peephole-rewriting paper that mentions quantum computing only as one example domain in passing (Bhat et al.), and 4 circuit-synthesis papers whose 'testing'/'accuracy' language refers to ML-model evaluation or general design-space exploration rather than software testing (da Cruz thesis, Weiden et al., Hwang, Islam et al.), plus one 2006 citation-only stub predating the SLR's 2015 search-window floor (Hayes & Markov). Duplicates of papers already in the corpus are not counted here.
A41: 13 | B41: 10 | D41: Round 13 (5 queries: fault injection, test-suite reduction, cross-version regression, SDK fuzzing, QEC decoder testing) confirmed two veins are now saturated with zero new papers (cross-version Qiskit-regression-testing, general fuzzing) — all hits were duplicates already in the corpus. Excluded: 1 security/adversarial fault-injection-attack paper (not a testing methodology study; Etim & Szefer), 1 physics/QEC-code-design paper (Ginsberg & Patel), 2 more instances of the quantum-annealing/QAOA-for-classical-test-suite-minimization confound (Sharma et al., Hussein et al.), 2 pre-2015 quantum-inspired-GA test-suite papers (also confound; Zhang et al. 2011, Kumari et al. 2012), and 4 hardware/physics QEC-decoder papers using 'testing' in the physics-experiment sense rather than software-testing sense (the Google below-threshold QEC paper, Bausch et al., Ryan-Anderson et al., Cruz et al.). Duplicates already in the corpus are not counted here.
A42: 14 | B42: 29 | D42: Round 14 (5 queries: QKD/quantum-cryptography testing, mock/test-double backends, comparative tool-evaluation surveys, pytket/tket-specific, TDD-practices) surfaced two important scope boundaries. First, quantum key distribution and quantum networking are a different subfield (quantum communication/cryptography hardware) from quantum-computing compiler/transpiler testing and returned zero relevant hits — all 10 QKD-query results excluded, including one post-quantum-cryptography false-positive (Bhargavan et al., 'quantum' meaning quantum-resistant classical crypto) and quantum-internet infrastructure (Dahlberg & Wehner, excluded from the backend-mocking query). Second, the test-driven-development-practices query returned almost entirely classical (non-quantum) TDD empirical literature, including several false-positive matches where 'quantum' appeared only as an ordinary English phrase ('quantum of work') rather than referring to quantum computing (Bhadauria, Ahmed et al.) — all 10 hits excluded. Also excluded: 1 hardware/EDA circuit-design paper using Qiskit as an implementation platform rather than studying testing itself (Misra et al.), 3 simulator/HPC-infrastructure papers with no testing-methodology focus (Shehata et al., Guerreschi et al., Kumaresan et al.), 2 broad metrics/confound-survey papers (Soubra et al., Zhang et al. systematic analysis), and 2 compilation-performance/language-design papers with no testing focus (Moore et al., Guppy). Duplicates already in the corpus are not counted here.
A43: 15 | B43: 11 | D43: Round 15 (5 queries: model-based testing/FSM, type systems for no-cloning correctness, quantum Hoare/separation logic, white-box structural coverage, Q#-specific bug studies) opened a substantial new formal-verification vein: quantum Hoare logic and separation logic (7 papers, including two highly-cited foundational works, Liu et al. 2019 CAV and Unruh 2019 POPL) and a type-systems/no-cloning-correctness cluster (6 papers). Excluded: 7 classical (non-quantum) finite-state-machine/model-based-testing papers returned by the MBT query, most with no quantum content at all or only a passing unrelated mention (Turker et al., Giorgio, Huang & Peleska, Sabbaghi & Keyvanpour, Onofrei et al., Salem), 1 pre-2015 foundational thesis (Valiron 2008) and 1 pre-2015 foundational Hoare-logic paper (Ying 2012, Floyd-Hoare logic — 301 citations but outside the SLR's 2015 search-window floor), 1 too-broad general-overview book chapter (Ding & Chong), and 1 saturated-area PhD thesis judged redundant with primary papers already well-represented (El Aoun). Duplicates already in the corpus (including a same-author arXiv companion of an included thesis) are not counted here.
...
